# `scipy.spatial.QhullError`

> 原文：[`docs.scipy.org/doc/scipy-1.12.0/reference/generated/scipy.spatial.QhullError.html#scipy.spatial.QhullError`](https://docs.scipy.org/doc/scipy-1.12.0/reference/generated/scipy.spatial.QhullError.html#scipy.spatial.QhullError)

```py
exception scipy.spatial.QhullError
```

```py
with_traceback()
```

Exception.with_traceback(tb) – set self.__traceback__ to tb and return self.
