# `scipy.odr.OdrWarning`

> 原文：[https://docs.scipy.org/doc/scipy-1.12.0/reference/generated/scipy.odr.OdrWarning.html#scipy.odr.OdrWarning](https://docs.scipy.org/doc/scipy-1.12.0/reference/generated/scipy.odr.OdrWarning.html#scipy.odr.OdrWarning)

```py
exception scipy.odr.OdrWarning
```

警告表明传递给 ODR 的数据在传递给 'odr' 时会导致问题，用户应当注意。

```py
with_traceback()
```

`Exception.with_traceback(tb) – 设置 self.__traceback__ 为 tb 并返回 self。`
