# `scipy.io.arff.ArffError`

> 原文：[`docs.scipy.org/doc/scipy-1.12.0/reference/generated/scipy.io.arff.ArffError.html#scipy.io.arff.ArffError`](https://docs.scipy.org/doc/scipy-1.12.0/reference/generated/scipy.io.arff.ArffError.html#scipy.io.arff.ArffError)

```py
exception scipy.io.arff.ArffError
```

```py
errno
```

POSIX 异常代码

```py
filename
```

异常文件名

```py
filename2
```

第二个异常文件名

```py
strerror
```

异常错误描述

```py
with_traceback()
```

Exception.with_traceback(tb) – 设置 self.__traceback__ 为 tb 并返回 self.
