# `scipy.special.SpecialFunctionError`

> 原文：[`docs.scipy.org/doc/scipy-1.12.0/reference/generated/scipy.special.SpecialFunctionError.html#scipy.special.SpecialFunctionError`](https://docs.scipy.org/doc/scipy-1.12.0/reference/generated/scipy.special.SpecialFunctionError.html#scipy.special.SpecialFunctionError)

```py
exception scipy.special.SpecialFunctionError
```

特殊函数可能引发的异常。

```py
with_traceback()
```

Exception.with_traceback(tb) – 将 self.__traceback__ 设置为 tb 并返回 self。
