- en: scipy.odr.OdrError
  id: totrans-0
  prefs:
  - PREF_H1
  type: TYPE_NORMAL
  zh: '`scipy.odr.OdrError`'
- en: Original text：[https://docs.scipy.org/doc/scipy-1.12.0/reference/generated/scipy.odr.OdrError.html#scipy.odr.OdrError](https://docs.scipy.org/doc/scipy-1.12.0/reference/generated/scipy.odr.OdrError.html#scipy.odr.OdrError)
  id: totrans-1
  prefs:
  - PREF_BQ
  type: TYPE_NORMAL
  zh: 原文：[https://docs.scipy.org/doc/scipy-1.12.0/reference/generated/scipy.odr.OdrError.html#scipy.odr.OdrError](https://docs.scipy.org/doc/scipy-1.12.0/reference/generated/scipy.odr.OdrError.html#scipy.odr.OdrError)
- en: '[PRE0]'
  id: totrans-2
  prefs: []
  type: TYPE_PRE
  zh: '[PRE0]'
- en: Exception indicating an error in fitting.
  id: totrans-3
  prefs: []
  type: TYPE_NORMAL
  zh: 表示拟合过程中出现的异常。
- en: This is raised by [`odr`](odr-function.html#scipy.odr.odr "scipy.odr.odr") if
    an error occurs during fitting.
  id: totrans-4
  prefs: []
  type: TYPE_NORMAL
  zh: 当拟合过程中发生错误时，[`odr`](odr-function.html#scipy.odr.odr "scipy.odr.odr") 会引发此异常。
- en: '[PRE1]'
  id: totrans-5
  prefs: []
  type: TYPE_PRE
  zh: '[PRE1]'
- en: Exception.with_traceback(tb) – set self.__traceback__ to tb and return self.
  id: totrans-6
  prefs: []
  type: TYPE_NORMAL
  zh: Exception.with_traceback(tb) – 设置 self.__traceback__ 为 tb 并返回 self。
