# `scipy.io.FortranFormattingError`

> 原文：[`docs.scipy.org/doc/scipy-1.12.0/reference/generated/scipy.io.FortranFormattingError.html#scipy.io.FortranFormattingError`](https://docs.scipy.org/doc/scipy-1.12.0/reference/generated/scipy.io.FortranFormattingError.html#scipy.io.FortranFormattingError)

```py
exception scipy.io.FortranFormattingError
```

表明文件在记录中途结束。

派生自 TypeError 以保持向后兼容性。

```py
errno
```

POSIX 异常代码

```py
filename
```

异常 filename

```py
filename2
```

第二个异常 filename

```py
strerror
```

异常 strerror

```py
with_traceback()
```

Exception.with_traceback(tb) – 设置 self.__traceback__ 为 tb 并返回 self。
