- en: scipy.linalg.LinAlgError
  id: totrans-0
  prefs:
  - PREF_H1
  type: TYPE_NORMAL
  zh: '`scipy.linalg.LinAlgError`'
- en: Original text：[https://docs.scipy.org/doc/scipy-1.12.0/reference/generated/scipy.linalg.LinAlgError.html#scipy.linalg.LinAlgError](https://docs.scipy.org/doc/scipy-1.12.0/reference/generated/scipy.linalg.LinAlgError.html#scipy.linalg.LinAlgError)
  id: totrans-1
  prefs:
  - PREF_BQ
  type: TYPE_NORMAL
  zh: 原文：[https://docs.scipy.org/doc/scipy-1.12.0/reference/generated/scipy.linalg.LinAlgError.html#scipy.linalg.LinAlgError](https://docs.scipy.org/doc/scipy-1.12.0/reference/generated/scipy.linalg.LinAlgError.html#scipy.linalg.LinAlgError)
- en: '[PRE0]'
  id: totrans-2
  prefs: []
  type: TYPE_PRE
  zh: '[PRE0]'
- en: Generic Python-exception-derived object raised by linalg functions.
  id: totrans-3
  prefs: []
  type: TYPE_NORMAL
  zh: 由 linalg 函数引发的基本 Python 异常对象。
- en: General purpose exception class, derived from Python’s ValueError class, programmatically
    raised in linalg functions when a Linear Algebra-related condition would prevent
    further correct execution of the function.
  id: totrans-4
  prefs: []
  type: TYPE_NORMAL
  zh: 通用目的的异常类，派生自 Python 的 ValueError 类，在 linalg 函数中以编程方式引发，当线性代数相关条件会阻止函数进一步正确执行时。
- en: 'Parameters:'
  id: totrans-5
  prefs: []
  type: TYPE_NORMAL
  zh: 'Parameters:'
- en: '**None**'
  id: totrans-6
  prefs: []
  type: TYPE_NORMAL
  zh: '**None**'
- en: Examples
  id: totrans-7
  prefs: []
  type: TYPE_NORMAL
  zh: Examples
- en: '[PRE1]'
  id: totrans-8
  prefs: []
  type: TYPE_PRE
  zh: '[PRE1]'
- en: '[PRE2]'
  id: totrans-9
  prefs: []
  type: TYPE_PRE
  zh: '[PRE2]'
- en: Exception.with_traceback(tb) – set self.__traceback__ to tb and return self.
  id: totrans-10
  prefs: []
  type: TYPE_NORMAL
  zh: '`Exception.with_traceback(tb)` – 将 self.__traceback__ 设置为 tb 并返回 self。'
