- en: scipy.stats.FitError
  id: totrans-0
  prefs:
  - PREF_H1
  type: TYPE_NORMAL
  zh: '`scipy.stats.FitError`'
- en: Original text：[https://docs.scipy.org/doc/scipy-1.12.0/reference/generated/scipy.stats.FitError.html#scipy.stats.FitError](https://docs.scipy.org/doc/scipy-1.12.0/reference/generated/scipy.stats.FitError.html#scipy.stats.FitError)
  id: totrans-1
  prefs:
  - PREF_BQ
  type: TYPE_NORMAL
  zh: 原文：[https://docs.scipy.org/doc/scipy-1.12.0/reference/generated/scipy.stats.FitError.html#scipy.stats.FitError](https://docs.scipy.org/doc/scipy-1.12.0/reference/generated/scipy.stats.FitError.html#scipy.stats.FitError)
- en: '[PRE0]'
  id: totrans-2
  prefs: []
  type: TYPE_PRE
  zh: '[PRE0]'
- en: Represents an error condition when fitting a distribution to data.
  id: totrans-3
  prefs: []
  type: TYPE_NORMAL
  zh: 表示拟合分布到数据时的错误条件。
- en: '[PRE1]'
  id: totrans-4
  prefs: []
  type: TYPE_PRE
  zh: '[PRE1]'
- en: Exception.with_traceback(tb) – set self.__traceback__ to tb and return self.
  id: totrans-5
  prefs: []
  type: TYPE_NORMAL
  zh: '`Exception.with_traceback(tb)` – 将 self.__traceback__ 设置为 tb 并返回 self。'
